<?xml version="1.0"?>
<robot name="linear_block_robot">

  <!-- Link Definitions -->
  <link name="block1">
    <visual>
      <origin xyz="0. 0 0" rpy="0 0 0"/>
      <geometry>
        <box size="1 0.35 3"/>
      </geometry>
    </visual>
    <collision>
      <origin xyz="0. 0 0" rpy="0 0 0"/>
      <geometry>
        <box size="1 0.35 3"/>
      </geometry>
    </collision>
    <inertial>
      <mass value="1"/> 
      <origin xyz="0. 0 0"/> 
      <inertia ixx="0.76" iyy="0.83" izz="0.094"/> 
    </inertial>
  </link>

  <link name="block2">
    <visual>
      <origin xyz="0.5 0 0" rpy="0 0 0"/> 
      <geometry>
        <box size="1 0.35 3"/>
      </geometry>
    </visual>
    <collision>
      <origin xyz="0.5 0 0" rpy="0 0 0"/>
      <geometry>
        <box size="1 0.35 3"/>
      </geometry>
    </collision>
    <inertial>
      <mass value="1"/> 
      <origin xyz="0.5 0 0"/> 
      <inertia ixx="0.76" iyy="0.83" izz="0.094"/> 
    </inertial>
  </link>

  <link name="block3">
    <visual>
      <origin xyz="0.5 0 0" rpy="0 0 0"/>
      <geometry>
        <box size="1 0.35 3"/>
      </geometry>
    </visual>
    <collision>
      <origin xyz="0.5 0 0" rpy="0 0 0"/>
      <geometry>
        <box size="1 0.35 3"/>
      </geometry>
    </collision>
    <inertial>
      <mass value="1"/> 
      <origin xyz="0.5 0 0"/> 
      <inertia ixx="0.76" iyy="0.83" izz="0.094"/> 
    </inertial>
  </link>

  <link name="block4">
    <visual>
      <origin xyz="0.5 0 0" rpy="0 0 0"/>
      <geometry>
        <box size="1 0.35 3"/>
      </geometry>
    </visual>
    <collision>
      <origin xyz="0.5 0 0" rpy="0 0 0"/>
      <geometry>
        <box size="1 0.35 3"/>
      </geometry>
    </collision>
    <inertial>
      <mass value="1"/> 
      <origin xyz="0.5 0 0"/> 
      <inertia ixx="0.76" iyy="0.83" izz="0.094"/> 
    </inertial>
  </link>

  <link name="block5">
    <visual>
      <origin xyz="0.5 0 0" rpy="0 0 0"/>
      <geometry>
        <box size="1 0.35 3"/>
      </geometry>
    </visual>
    <collision>
      <origin xyz="0.5 0 0" rpy="0 0 0"/>
      <geometry>
        <box size="1 0.35 3"/>
      </geometry>
    </collision>
    <inertial>
      <mass value="1"/> 
      <origin xyz="0.5 0 0"/> 
      <inertia ixx="0.76" iyy="0.83" izz="0.094"/> 
    </inertial>
  </link>

  <!-- Joint Definitions -->
  <joint name="joint1" type="revolute">
    <parent link="block1"/>
    <child link="block2"/>
    <origin xyz="0.5 0 0" rpy="0 0 0"/>
    <axis xyz="0 0 1"/>
    <limit effort="1000" lower="-.57" upper=".57" velocity="50"/>
    <dynamics damping="0.001" friction="0.001"/>
  </joint>

  <joint name="joint2" type="revolute">
    <parent link="block2"/>
    <child link="block3"/>
    <origin xyz="1 0 0" rpy="0 0 0"/>
    <axis xyz="0 0 1"/>
    <limit effort="1000" lower="-.57" upper=".57" velocity="50"/>
    <dynamics damping="0.001" friction="0.001"/>
  </joint>

  <joint name="joint3" type="revolute">
    <parent link="block3"/>
    <child link="block4"/>
    <origin xyz="1 0 0" rpy="0 0 0"/>
    <axis xyz="0 0 1"/>
    <limit effort="1000" lower="-.57" upper=".57" velocity="50"/>
    <dynamics damping="0.001" friction="0.001"/>
  </joint>

  <joint name="joint4" type="revolute">
    <parent link="block4"/>
    <child link="block5"/>
    <origin xyz="1 0 0" rpy="0 0 0"/>
    <axis xyz="0 0 1"/>
    <limit effort="1000" lower="-.57" upper=".57" velocity="50"/>
    <dynamics damping="0.001" friction="0.001"/>
  </joint>

</robot>