<?xml version="1.0" ?>
<robot name="lc_soft_enable_wide_grip">
	<link name="base_link">
		<collision>
			<geometry>
				<mesh filename="package://lc_soft_enable_wide_grip/meshes/lc_soft_enable_wide_grip_Base_SWA_collision.stl" scale="1.0 1.0 1.0"/>
			</geometry>
			<origin rpy="0 0 0" xyz="0 0 0"/>
		</collision>
		<visual>
			<geometry>
				<mesh filename="package://lc_soft_enable_wide_grip/meshes/lc_soft_enable_wide_grip_Base_SWA.stl" scale="1.0 1.0 1.0"/>
			</geometry>
			<origin rpy="0 0 0" xyz="0 0 0"/>
			<material name="lc_soft_enable_wide_grip_Base_SWA.stl">
				<color rgba="0.4891 0.5125 0.5281 1.0"/>
			</material>
		</visual>
		<inertial>
			<inertia ixx="0.0024968641" ixy="6.6188362e-07" ixz="3.2766678e-07" iyy="0.0022605853" iyz="2.8256704e-05" izz="0.0011041847"/>
			<origin rpy="0 0 0" xyz="8.1210522e-06 0.0054439341 0.062857511"/>
			<mass value="1.0848835"/>
		</inertial>
	</link>
	<link name="right_finger_link">
		<collision>
			<geometry>
				<mesh filename="package://lc_soft_enable_wide_grip/meshes/lc_soft_enable_wide_grip_Right_Base_RIGHT_BASE_collision.stl" scale="1.0 1.0 1.0"/>
			</geometry>
			<origin rpy="0 0 0" xyz="0 0 0"/>
		</collision>
		<visual>
			<geometry>
				<mesh filename="package://lc_soft_enable_wide_grip/meshes/lc_soft_enable_wide_grip_Right_Base_RIGHT_BASE.stl" scale="1.0 1.0 1.0"/>
			</geometry>
			<origin rpy="0 0 0" xyz="0 0 0"/>
			<material name="lc_soft_enable_wide_grip_Right_Base_RIGHT_BASE.stl">
				<color rgba="0.4891 0.5125 0.5281 1.0"/>
			</material>
		</visual>
		<inertial>
			<inertia ixx="5.6721146e-06" ixy="5.9532085e-07" ixz="-2.4613328e-06" iyy="1.8932328e-05" iyz="-1.2413427e-07" izz="1.9250009e-05"/>
			<origin rpy="0 0 0" xyz="0.033757146 -0.0013155141 0.0053506039"/>
			<mass value="0.045621669"/>
		</inertial>
	</link>
	<link name="right_tip_link">
		<collision>
			<geometry>
				<mesh filename="package://lc_soft_enable_wide_grip/meshes/lc_soft_enable_wide_grip_Right_Distal_RIGHT_DISTAL_collision.stl" scale="1.0 1.0 1.0"/>
			</geometry>
			<origin rpy="0 0 0" xyz="0 0 0"/>
		</collision>
		<visual>
			<geometry>
				<mesh filename="package://lc_soft_enable_wide_grip/meshes/lc_soft_enable_wide_grip_Right_Distal_RIGHT_DISTAL.stl" scale="1.0 1.0 1.0"/>
			</geometry>
			<origin rpy="0 0 0" xyz="0 0 0"/>
			<material name="lc_soft_enable_wide_grip_Right_Distal_RIGHT_DISTAL.stl">
				<color rgba="0.4891 0.5125 0.5281 1.0"/>
			</material>
		</visual>
		<inertial>
			<inertia ixx="2.3062249e-06" ixy="2.4935694e-07" ixz="-3.3804361e-09" iyy="2.4678917e-06" iyz="9.6184869e-09" izz="6.2021464e-07"/>
			<origin rpy="0 0 0" xyz="-0.0084666725 0.0065304494 0.0001563758"/>
			<mass value="0.013215129"/>
		</inertial>
	</link>
	<link name="left_finger">
		<collision>
			<geometry>
				<mesh filename="package://lc_soft_enable_wide_grip/meshes/lc_soft_enable_wide_grip_Left_Base_left_base_collision.stl" scale="1.0 1.0 1.0"/>
			</geometry>
			<origin rpy="0 0 0" xyz="0 0 0"/>
		</collision>
		<visual>
			<geometry>
				<mesh filename="package://lc_soft_enable_wide_grip/meshes/lc_soft_enable_wide_grip_Left_Base_left_base.stl" scale="1.0 1.0 1.0"/>
			</geometry>
			<origin rpy="0 0 0" xyz="0 0 0"/>
			<material name="lc_soft_enable_wide_grip_Left_Base_left_base.stl">
				<color rgba="0.4891 0.5125 0.5281 1.0"/>
			</material>
		</visual>
		<inertial>
			<inertia ixx="5.661498e-06" ixy="6.1007559e-07" ixz="-2.4248062e-06" iyy="1.8602714e-05" iyz="-1.2251705e-07" izz="1.8928672e-05"/>
			<origin rpy="0 0 0" xyz="0.033520301 -0.0013264928 0.0053246441"/>
			<mass value="0.045257797"/>
		</inertial>
	</link>
	<link name="left_tip_link">
		<collision>
			<geometry>
				<mesh filename="package://lc_soft_enable_wide_grip/meshes/lc_soft_enable_wide_grip_Left_Distal_LEFT_DISTAL_collision.stl" scale="1.0 1.0 1.0"/>
			</geometry>
			<origin rpy="0 0 0" xyz="0 0 0"/>
		</collision>
		<visual>
			<geometry>
				<mesh filename="package://lc_soft_enable_wide_grip/meshes/lc_soft_enable_wide_grip_Left_Distal_LEFT_DISTAL.stl" scale="1.0 1.0 1.0"/>
			</geometry>
			<origin rpy="0 0 0" xyz="0 0 0"/>
			<material name="lc_soft_enable_wide_grip_Left_Distal_LEFT_DISTAL.stl">
				<color rgba="0.4891 0.5125 0.5281 1.0"/>
			</material>
		</visual>
		<inertial>
			<inertia ixx="2.3062249e-06" ixy="2.4935694e-07" ixz="-3.3804361e-09" iyy="2.4678917e-06" iyz="9.6184869e-09" izz="6.2021464e-07"/>
			<origin rpy="0 0 0" xyz="-0.0084666725 0.0065304494 0.0001563758"/>
			<mass value="0.013215129"/>
		</inertial>
	</link>
	<joint name="right_finger" type="prismatic">
		<parent link="base_link"/>
		<child link="right_finger_link"/>
		<axis xyz="0 0 1"/>
		<limit effort="100000000000000000" lower="0" upper="0.0575" velocity="100000000000000000"/>
		<origin rpy="-3.141592653589793 -1.5707963057214722 0" xyz="-0.07658 -4.689172593935216e-18 0.1335"/>
	</joint>
	<joint name="right_tip" type="revolute">
		<parent link="right_finger_link"/>
		<child link="right_tip_link"/>
		<axis xyz="0 0 1"/>
		<limit effort="100000000000000000" lower="0" upper="1.0471975511965976" velocity="100000000000000000"/>
		<origin rpy="-1.5707963267948963 0.87266404218453 3.141592653589793" xyz="0.06859 9.41141065144741e-19 0.01537"/>
	</joint>
	<joint name="left_base" type="prismatic">
		<parent link="base_link"/>
		<child link="left_finger"/>
		<axis xyz="0 0 1"/>
		<limit effort="100000000000000000" lower="0" upper="0.0575" velocity="100000000000000000"/>
		<origin rpy="1.874699728327322e-33 -1.5707963057214722 0" xyz="0.07658 4.689172593935216e-18 0.1335"/>
	</joint>
	<joint name="left_tip" type="revolute">
		<parent link="left_finger"/>
		<child link="left_tip_link"/>
		<axis xyz="0 0 1"/>
		<limit effort="100000000000000000" lower="0" upper="1.0471975511965976" velocity="100000000000000000"/>
		<origin rpy="-1.5707963267948968 0.8726640421845309 3.141592653589793" xyz="0.06859 -9.41141065144741e-19 0.01537"/>
	</joint>
</robot>
